2023-03-03 22:42:31,086 ERROR: Exception on /admit_patient [POST] [in /home/tfjuror/anaconda3/lib/python3.7/site-packages/flask/app.py:1455]
Traceback (most recent call last):
  File "/home/tfjuror/anaconda3/lib/python3.7/site-packages/sqlalchemy/engine/base.py", line 1771, in _execute_context
    cursor, statement, parameters, context
  File "/home/tfjuror/anaconda3/lib/python3.7/site-packages/sqlalchemy/engine/default.py", line 717, in do_execute
    cursor.execute(statement, parameters)
  File "/home/tfjuror/anaconda3/lib/python3.7/site-packages/pymysql/cursors.py", line 148, in execute
    result = self._query(query)
  File "/home/tfjuror/anaconda3/lib/python3.7/site-packages/pymysql/cursors.py", line 310, in _query
    conn.query(q)
  File "/home/tfjuror/anaconda3/lib/python3.7/site-packages/pymysql/connections.py", line 548, in query
    self._affected_rows = self._read_query_result(unbuffered=unbuffered)
  File "/home/tfjuror/anaconda3/lib/python3.7/site-packages/pymysql/connections.py", line 775, in _read_query_result
    result.read()
  File "/home/tfjuror/anaconda3/lib/python3.7/site-packages/pymysql/connections.py", line 1156, in read
    first_packet = self.connection._read_packet()
  File "/home/tfjuror/anaconda3/lib/python3.7/site-packages/pymysql/connections.py", line 725, in _read_packet
    packet.raise_for_error()
  File "/home/tfjuror/anaconda3/lib/python3.7/site-packages/pymysql/protocol.py", line 221, in raise_for_error
    err.raise_mysql_exception(self._data)
  File "/home/tfjuror/anaconda3/lib/python3.7/site-packages/pymysql/err.py", line 143, in raise_mysql_exception
    raise errorclass(errno, errval)
pymysql.err.IntegrityError: (1048, "Column 'End' cannot be null")

The above exception was the direct cause of the following exception:

Traceback (most recent call last):
  File "/home/tfjuror/anaconda3/lib/python3.7/site-packages/flask/app.py", line 2070, in wsgi_app
    response = self.full_dispatch_request()
  File "/home/tfjuror/anaconda3/lib/python3.7/site-packages/flask/app.py", line 1515, in full_dispatch_request
    rv = self.handle_user_exception(e)
  File "/home/tfjuror/anaconda3/lib/python3.7/site-packages/flask/app.py", line 1513, in full_dispatch_request
    rv = self.dispatch_request()
  File "/home/tfjuror/anaconda3/lib/python3.7/site-packages/flask/app.py", line 1499, in dispatch_request
    return self.ensure_sync(self.view_functions[rule.endpoint])(**req.view_args)
  File "/home/tfjuror/anaconda3/lib/python3.7/site-packages/flask_login/utils.py", line 272, in decorated_view
    return func(*args, **kwargs)
  File "/home/tfjuror/Desktop/Courses/DBMS/Lab/DBMS-MiniProject-2023S/app/routes.py", line 127, in admit_patient
    db.session.commit()
  File "<string>", line 2, in commit
  File "/home/tfjuror/anaconda3/lib/python3.7/site-packages/sqlalchemy/orm/session.py", line 1428, in commit
    self._transaction.commit(_to_root=self.future)
  File "/home/tfjuror/anaconda3/lib/python3.7/site-packages/sqlalchemy/orm/session.py", line 829, in commit
    self._prepare_impl()
  File "/home/tfjuror/anaconda3/lib/python3.7/site-packages/sqlalchemy/orm/session.py", line 808, in _prepare_impl
    self.session.flush()
  File "/home/tfjuror/anaconda3/lib/python3.7/site-packages/sqlalchemy/orm/session.py", line 3298, in flush
    self._flush(objects)
  File "/home/tfjuror/anaconda3/lib/python3.7/site-packages/sqlalchemy/orm/session.py", line 3438, in _flush
    transaction.rollback(_capture_exception=True)
  File "/home/tfjuror/anaconda3/lib/python3.7/site-packages/sqlalchemy/util/langhelpers.py", line 72, in __exit__
    with_traceback=exc_tb,
  File "/home/tfjuror/anaconda3/lib/python3.7/site-packages/sqlalchemy/util/compat.py", line 207, in raise_
    raise exception
  File "/home/tfjuror/anaconda3/lib/python3.7/site-packages/sqlalchemy/orm/session.py", line 3398, in _flush
    flush_context.execute()
  File "/home/tfjuror/anaconda3/lib/python3.7/site-packages/sqlalchemy/orm/unitofwork.py", line 456, in execute
    rec.execute(self)
  File "/home/tfjuror/anaconda3/lib/python3.7/site-packages/sqlalchemy/orm/unitofwork.py", line 633, in execute
    uow,
  File "/home/tfjuror/anaconda3/lib/python3.7/site-packages/sqlalchemy/orm/persistence.py", line 247, in save_obj
    insert,
  File "/home/tfjuror/anaconda3/lib/python3.7/site-packages/sqlalchemy/orm/persistence.py", line 1095, in _emit_insert_statements
    statement, multiparams, execution_options=execution_options
  File "/home/tfjuror/anaconda3/lib/python3.7/site-packages/sqlalchemy/engine/base.py", line 1582, in _execute_20
    return meth(self, args_10style, kwargs_10style, execution_options)
  File "/home/tfjuror/anaconda3/lib/python3.7/site-packages/sqlalchemy/sql/elements.py", line 324, in _execute_on_connection
    self, multiparams, params, execution_options
  File "/home/tfjuror/anaconda3/lib/python3.7/site-packages/sqlalchemy/engine/base.py", line 1461, in _execute_clauseelement
    cache_hit=cache_hit,
  File "/home/tfjuror/anaconda3/lib/python3.7/site-packages/sqlalchemy/engine/base.py", line 1814, in _execute_context
    e, statement, parameters, cursor, context
  File "/home/tfjuror/anaconda3/lib/python3.7/site-packages/sqlalchemy/engine/base.py", line 1995, in _handle_dbapi_exception
    sqlalchemy_exception, with_traceback=exc_info[2], from_=e
  File "/home/tfjuror/anaconda3/lib/python3.7/site-packages/sqlalchemy/util/compat.py", line 207, in raise_
    raise exception
  File "/home/tfjuror/anaconda3/lib/python3.7/site-packages/sqlalchemy/engine/base.py", line 1771, in _execute_context
    cursor, statement, parameters, context
  File "/home/tfjuror/anaconda3/lib/python3.7/site-packages/sqlalchemy/engine/default.py", line 717, in do_execute
    cursor.execute(statement, parameters)
  File "/home/tfjuror/anaconda3/lib/python3.7/site-packages/pymysql/cursors.py", line 148, in execute
    result = self._query(query)
  File "/home/tfjuror/anaconda3/lib/python3.7/site-packages/pymysql/cursors.py", line 310, in _query
    conn.query(q)
  File "/home/tfjuror/anaconda3/lib/python3.7/site-packages/pymysql/connections.py", line 548, in query
    self._affected_rows = self._read_query_result(unbuffered=unbuffered)
  File "/home/tfjuror/anaconda3/lib/python3.7/site-packages/pymysql/connections.py", line 775, in _read_query_result
    result.read()
  File "/home/tfjuror/anaconda3/lib/python3.7/site-packages/pymysql/connections.py", line 1156, in read
    first_packet = self.connection._read_packet()
  File "/home/tfjuror/anaconda3/lib/python3.7/site-packages/pymysql/connections.py", line 725, in _read_packet
    packet.raise_for_error()
  File "/home/tfjuror/anaconda3/lib/python3.7/site-packages/pymysql/protocol.py", line 221, in raise_for_error
    err.raise_mysql_exception(self._data)
  File "/home/tfjuror/anaconda3/lib/python3.7/site-packages/pymysql/err.py", line 143, in raise_mysql_exception
    raise errorclass(errno, errval)
sqlalchemy.exc.IntegrityError: (pymysql.err.IntegrityError) (1048, "Column 'End' cannot be null")
[SQL: INSERT INTO `Stay` (`StayID`, `Patient`, `Room`, `Start`, `End`) VALUES (%(StayID)s, %(Patient)s, %(Room)s, %(Start)s, %(End)s)]
[parameters: {'StayID': 1, 'Patient': 1, 'Room': 1, 'Start': datetime.date(2022, 3, 3), 'End': None}]
(Background on this error at: http://sqlalche.me/e/14/gkpj)
2023-03-03 22:43:15,575 INFO: HMS startup [in /home/tfjuror/Desktop/Courses/DBMS/Lab/DBMS-MiniProject-2023S/app/__init__.py:52]
2023-03-03 22:43:17,791 INFO: HMS startup [in /home/tfjuror/Desktop/Courses/DBMS/Lab/DBMS-MiniProject-2023S/app/__init__.py:52]
