2023-03-03 23:59:18,639 ERROR: Exception on /schedule_appointment [POST] [in /home/tfjuror/anaconda3/lib/python3.7/site-packages/flask/app.py:1455]
Traceback (most recent call last):
  File "/home/tfjuror/anaconda3/lib/python3.7/site-packages/sqlalchemy/engine/base.py", line 1771, in _execute_context
    cursor, statement, parameters, context
  File "/home/tfjuror/anaconda3/lib/python3.7/site-packages/sqlalchemy/engine/default.py", line 717, in do_execute
    cursor.execute(statement, parameters)
  File "/home/tfjuror/anaconda3/lib/python3.7/site-packages/pymysql/cursors.py", line 148, in execute
    result = self._query(query)
  File "/home/tfjuror/anaconda3/lib/python3.7/site-packages/pymysql/cursors.py", line 310, in _query
    conn.query(q)
  File "/home/tfjuror/anaconda3/lib/python3.7/site-packages/pymysql/connections.py", line 548, in query
    self._affected_rows = self._read_query_result(unbuffered=unbuffered)
  File "/home/tfjuror/anaconda3/lib/python3.7/site-packages/pymysql/connections.py", line 775, in _read_query_result
    result.read()
  File "/home/tfjuror/anaconda3/lib/python3.7/site-packages/pymysql/connections.py", line 1156, in read
    first_packet = self.connection._read_packet()
  File "/home/tfjuror/anaconda3/lib/python3.7/site-packages/pymysql/connections.py", line 725, in _read_packet
    packet.raise_for_error()
  File "/home/tfjuror/anaconda3/lib/python3.7/site-packages/pymysql/protocol.py", line 221, in raise_for_error
    err.raise_mysql_exception(self._data)
  File "/home/tfjuror/anaconda3/lib/python3.7/site-packages/pymysql/err.py", line 143, in raise_mysql_exception
    raise errorclass(errno, errval)
pymysql.err.OperationalError: (1054, "Unknown column 'Appointment.Date' in 'field list'")

The above exception was the direct cause of the following exception:

Traceback (most recent call last):
  File "/home/tfjuror/anaconda3/lib/python3.7/site-packages/flask/app.py", line 2070, in wsgi_app
    response = self.full_dispatch_request()
  File "/home/tfjuror/anaconda3/lib/python3.7/site-packages/flask/app.py", line 1515, in full_dispatch_request
    rv = self.handle_user_exception(e)
  File "/home/tfjuror/anaconda3/lib/python3.7/site-packages/flask/app.py", line 1513, in full_dispatch_request
    rv = self.dispatch_request()
  File "/home/tfjuror/anaconda3/lib/python3.7/site-packages/flask/app.py", line 1499, in dispatch_request
    return self.ensure_sync(self.view_functions[rule.endpoint])(**req.view_args)
  File "/home/tfjuror/anaconda3/lib/python3.7/site-packages/flask_login/utils.py", line 272, in decorated_view
    return func(*args, **kwargs)
  File "/home/tfjuror/Desktop/Courses/DBMS/Lab/DBMS-MiniProject-2023S/app/routes.py", line 166, in schedule_appointment
    earlier_appointment_patient = Appointment.query.filter(Appointment.Patient == form.patient.data).filter(Appointment.Date == form.date.data).filter(Appointment.StartTime >= form.start_time.data).filter(Appointment.EndTime <= form.end_time.data).first()
  File "/home/tfjuror/anaconda3/lib/python3.7/site-packages/sqlalchemy/orm/query.py", line 2760, in first
    return self.limit(1)._iter().first()
  File "/home/tfjuror/anaconda3/lib/python3.7/site-packages/sqlalchemy/orm/query.py", line 2847, in _iter
    execution_options={"_sa_orm_load_options": self.load_options},
  File "/home/tfjuror/anaconda3/lib/python3.7/site-packages/sqlalchemy/orm/session.py", line 1689, in execute
    result = conn._execute_20(statement, params or {}, execution_options)
  File "/home/tfjuror/anaconda3/lib/python3.7/site-packages/sqlalchemy/engine/base.py", line 1582, in _execute_20
    return meth(self, args_10style, kwargs_10style, execution_options)
  File "/home/tfjuror/anaconda3/lib/python3.7/site-packages/sqlalchemy/sql/elements.py", line 324, in _execute_on_connection
    self, multiparams, params, execution_options
  File "/home/tfjuror/anaconda3/lib/python3.7/site-packages/sqlalchemy/engine/base.py", line 1461, in _execute_clauseelement
    cache_hit=cache_hit,
  File "/home/tfjuror/anaconda3/lib/python3.7/site-packages/sqlalchemy/engine/base.py", line 1814, in _execute_context
    e, statement, parameters, cursor, context
  File "/home/tfjuror/anaconda3/lib/python3.7/site-packages/sqlalchemy/engine/base.py", line 1995, in _handle_dbapi_exception
    sqlalchemy_exception, with_traceback=exc_info[2], from_=e
  File "/home/tfjuror/anaconda3/lib/python3.7/site-packages/sqlalchemy/util/compat.py", line 207, in raise_
    raise exception
  File "/home/tfjuror/anaconda3/lib/python3.7/site-packages/sqlalchemy/engine/base.py", line 1771, in _execute_context
    cursor, statement, parameters, context
  File "/home/tfjuror/anaconda3/lib/python3.7/site-packages/sqlalchemy/engine/default.py", line 717, in do_execute
    cursor.execute(statement, parameters)
  File "/home/tfjuror/anaconda3/lib/python3.7/site-packages/pymysql/cursors.py", line 148, in execute
    result = self._query(query)
  File "/home/tfjuror/anaconda3/lib/python3.7/site-packages/pymysql/cursors.py", line 310, in _query
    conn.query(q)
  File "/home/tfjuror/anaconda3/lib/python3.7/site-packages/pymysql/connections.py", line 548, in query
    self._affected_rows = self._read_query_result(unbuffered=unbuffered)
  File "/home/tfjuror/anaconda3/lib/python3.7/site-packages/pymysql/connections.py", line 775, in _read_query_result
    result.read()
  File "/home/tfjuror/anaconda3/lib/python3.7/site-packages/pymysql/connections.py", line 1156, in read
    first_packet = self.connection._read_packet()
  File "/home/tfjuror/anaconda3/lib/python3.7/site-packages/pymysql/connections.py", line 725, in _read_packet
    packet.raise_for_error()
  File "/home/tfjuror/anaconda3/lib/python3.7/site-packages/pymysql/protocol.py", line 221, in raise_for_error
    err.raise_mysql_exception(self._data)
  File "/home/tfjuror/anaconda3/lib/python3.7/site-packages/pymysql/err.py", line 143, in raise_mysql_exception
    raise errorclass(errno, errval)
sqlalchemy.exc.OperationalError: (pymysql.err.OperationalError) (1054, "Unknown column 'Appointment.Date' in 'field list'")
[SQL: SELECT `Appointment`.`AppointmentID` AS `Appointment_AppointmentID`, `Appointment`.`Patient` AS `Appointment_Patient`, `Appointment`.`PrepNurse` AS `Appointment_PrepNurse`, `Appointment`.`Physician` AS `Appointment_Physician`, `Appointment`.`Date` AS `Appointment_Date`, `Appointment`.`StartTime` AS `Appointment_StartTime`, `Appointment`.`EndTime` AS `Appointment_EndTime` 
FROM `Appointment` 
WHERE `Appointment`.`Patient` = %(Patient_1)s AND `Appointment`.`Date` = %(Date_1)s AND `Appointment`.`StartTime` >= %(StartTime_1)s AND `Appointment`.`EndTime` <= %(EndTime_1)s 
 LIMIT %(param_1)s]
[parameters: {'Patient_1': 9, 'Date_1': datetime.date(2023, 3, 5), 'StartTime_1': datetime.time(10, 30), 'EndTime_1': datetime.time(11, 0), 'param_1': 1}]
(Background on this error at: http://sqlalche.me/e/14/e3q8)
2023-03-03 23:59:54,566 INFO: HMS startup [in /home/tfjuror/Desktop/Courses/DBMS/Lab/DBMS-MiniProject-2023S/app/__init__.py:52]
2023-03-04 00:00:02,707 INFO: HMS startup [in /home/tfjuror/Desktop/Courses/DBMS/Lab/DBMS-MiniProject-2023S/app/__init__.py:52]
2023-03-04 00:00:11,222 INFO: HMS startup [in /home/tfjuror/Desktop/Courses/DBMS/Lab/DBMS-MiniProject-2023S/app/__init__.py:52]
